<?xml version="1.0" encoding="utf-8"?>
  <!-- j5_Link -->
  <robot>
    <link name="lowerarm_preroll_d">
        <visual>
        <origin xyz="0.084 0 -0.012" rpy="0 0 0" />
        <geometry>
          <box size=".02 .05 .05" />
        </geometry>
        <material name="not Cyan">
          <color rgba="1 0.7 0.7 1"/>
        </material>
      </visual>
      </link>

      <joint name="fastswitch" type="fixed">
        <origin rpy="0 0 0" xyz="0.00 -0.015 0"/>
        <parent link="lowerarm_preroll_u"/>
        <child link="lowerarm_preroll_d"/>

      </joint>

  <!-- j6_Link -->
  <link
    name="lowerarm">
    <inertial>
      <origin
        xyz="0.063088 -4.524E-06 0.010537"
        rpy="0 0 0" />
      <mass
        value="0.088554" />
      <inertia
        ixx="3.269E-05"
        ixy="2.0124E-07"
        ixz="-1.6433E-05"
        iyy="7.2394E-05"
        iyz="1.982E-07"
        izz="6.9913E-05" />
    </inertial>
    <visual>
      <origin
        xyz="0.09 0 0.01"
        rpy="0 0 0" />
      <geometry>
        <box size=".16 .033 .052" />
      </geometry>
      <material
        name="">
        <color
          rgba="0.79216 0.81961 0.93333 1" />
      </material>
    </visual>
    <collision>
      <origin
        xyz="0.09 0 0.01"
        rpy="0 0 0" />
      <geometry>
        <box size=".16 .033 .052" />
      </geometry>
    </collision>
  </link>

  <!-- j6 -->
  <joint
    name="forearm_roll"
    type="revolute">
    <origin
      xyz="0.0795 0.00025 -0.025"
      rpy="0 0 0" />
    <parent
      link="lowerarm_preroll_d" />
    <child
      link="lowerarm" />
    <axis
      xyz="1 0 0" />
    <!-- <limit
      lower="-1.5708"
      upper="1.5708"
      effort="0"
      velocity="0" /> -->
    <limit effort="0" lower="-2.7489" upper="2.7489" velocity="1.0"/>
  </joint>

  <!-- j7_Link -->
  <link
    name="wrist">
    <inertial>
      <origin
        xyz="0.09547 -0.0036816 -0.028022"
        rpy="0 0 0" />
      <mass
        value="0.20597" />
      <inertia
        ixx="0.00034354"
        ixy="1.9986E-06"
        ixz="3.1921E-05"
        iyy="0.00045939"
        iyz="2.5997E-08"
        izz="0.00046029" />
    </inertial>
    <visual>
      <origin
        xyz="0.073 0 0"
        rpy="0 0 0" />
      <geometry>
        <box size=".146 .06 .015" />
      </geometry>
      <material
        name="">
        <color
          rgba="0.79216 0.81961 0.93333 1" />
      </material>
    </visual>
    <collision>
      <origin
        xyz="0.073 0 0"
        rpy="0 0 0" />
      <geometry>
        <box size=".146 .06 .015" />
      </geometry>
    </collision>
  </link>

  <!-- j7 -->
  <joint
    name="wrist_pitch"
    type="revolute">
    <origin
      xyz="0.15 0 0.009003"
      rpy="0 0 0" />
    <parent
      link="lowerarm" />
    <child
      link="wrist" />
    <axis
      xyz="0 1 0" />
      <!-- <limit
        lower="-1.5708"
        upper="1.5708"
        effort="0"
        velocity="0" /> -->
      <limit effort="0" lower="-1.5" upper="1.68" velocity="1.0"/>
  </joint>
</robot>
